<?xml version="1.0" ?>
<robot name="14402" version="1.0">
  <link name="link_0">
    <inertial>
      <origin rpy="0.0 0.0 0.0" xyz="0.0 0.0 0.0"/>
      <mass value="0.0"/>
      <inertia ixx="0.001" ixy="0.0" ixz="0.0" iyy="0.001" iyz="0.0" izz="0.001"/>
    </inertial>
    <visual name="link_0___1">
      <origin rpy="0.0 0.0 0.0" xyz="0.0 0.10708878402483918 0.09553159894775255"/>
      <geometry>
        <mesh filename="shape/visual/link_0_m1_vm.obj"/>
      </geometry>
    </visual>
    <collision>
      <origin rpy="0.0 0.0 0.0" xyz="0.0 0.10708878402483918 0.09553159894775255"/>
      <geometry>
        <mesh filename="shape/collision/link_0_cm.obj"/>
      </geometry>
    </collision>
  </link>
  <link name="link_1">
    <inertial>
      <origin rpy="0.0 0.0 0.0" xyz="0.0 0.0 0.0"/>
      <mass value="0.0"/>
      <inertia ixx="0.001" ixy="0.0" ixz="0.0" iyy="0.001" iyz="0.0" izz="0.001"/>
    </inertial>
    <visual name="link_1___3">
      <origin rpy="0.0 0.0 0.0" xyz="0.000694675896766978 0.11138200000000001 0.0"/>
      <geometry>
        <mesh filename="shape/visual/link_1_m3_vm.obj"/>
      </geometry>
    </visual>
    <collision>
      <origin rpy="0.0 0.0 0.0" xyz="0.000694675896766978 0.11138200000000001 0.0"/>
      <geometry>
        <mesh filename="shape/collision/link_1_cm.obj"/>
      </geometry>
    </collision>
  </link>
  <link name="base_link">
    <inertial>
      <origin rpy="0.0 0.0 0.0" xyz="0.0 0.0 0.0"/>
      <mass value="0.0"/>
      <inertia ixx="0.001" ixy="0.0" ixz="0.0" iyy="0.001" iyz="0.0" izz="0.001"/>
    </inertial>
    <visual name="link_2___2">
      <origin rpy="0.0 0.0 0.0" xyz="0.0 -0.0 0.0"/>
      <geometry>
        <mesh filename="shape/visual/link_2_m2_vm.obj"/>
      </geometry>
    </visual>
    <visual name="link_2___1">
      <origin rpy="0.0 0.0 0.0" xyz="0.0 -0.0 0.0"/>
      <geometry>
        <mesh filename="shape/visual/link_2_m1_vm.obj"/>
      </geometry>
    </visual>
    <collision>
      <origin rpy="0.0 0.0 0.0" xyz="0.0 -0.0 0.0"/>
      <geometry>
        <mesh filename="shape/collision/link_2_cm.obj"/>
      </geometry>
    </collision>
  </link>
  <link name="link_3">
    <inertial>
      <origin rpy="0.0 0.0 0.0" xyz="0.0 0.0 0.0"/>
      <mass value="0.0"/>
      <inertia ixx="0.001" ixy="0.0" ixz="0.0" iyy="0.001" iyz="0.0" izz="0.001"/>
    </inertial>
    <visual name="link_3___1">
      <origin rpy="0.0 0.0 0.0" xyz="0.0 -0.2426725 0.2173525"/>
      <geometry>
        <mesh filename="shape/visual/link_3_m1_vm.obj"/>
      </geometry>
    </visual>
    <collision>
      <origin rpy="0.0 0.0 0.0" xyz="0.0 -0.2426725 0.2173525"/>
      <geometry>
        <mesh filename="shape/collision/link_3_cm.obj"/>
      </geometry>
    </collision>
  </link>
  <joint name="joint_0" type="revolute">
    <origin rpy="0.0 0.0 0.0" xyz="0.0 -0.3497612840248392 0.12182090105224745"/>
    <axis xyz="1.0 -0.0 0.0"/>
    <parent link="link_3"/>
    <child link="link_0"/>
    <limit lower="-0.7853981633974483" upper="0.7853981633974483"/>
  </joint>
  <joint name="joint_1" type="continuous">
    <origin rpy="0.0 0.0 0.0" xyz="-0.000694675896766978 -0.00429321597516083 0.09553159894775255"/>
    <axis xyz="0.0 -0.0 1.0"/>
    <parent link="link_0"/>
    <child link="link_1"/>
  </joint>
  <joint name="joint_3" type="revolute">
    <origin rpy="0.0 0.0 0.0" xyz="0.0 0.2426725 -0.2173525"/>
    <axis xyz="1.0 -0.0 0.0"/>
    <parent link="base_link"/>
    <child link="link_3"/>
    <limit lower="-0.7853981633974483" upper="0.7853981633974483"/>
  </joint>
</robot>