<?xml version="1.0" ?>
<robot name="3393" version="1.0">
  <link name="link_0">
    <inertial>
      <origin rpy="0.0 0.0 0.0" xyz="0.0 0.0 0.0"/>
      <mass value="0.0"/>
      <inertia ixx="0.001" ixy="0.0" ixz="0.0" iyy="0.001" iyz="0.0" izz="0.001"/>
    </inertial>
    <visual name="link_0___2">
      <origin rpy="0.0 0.0 0.0" xyz="-0.10573799999999967 -0.1701922147503286 -0.1589604817222954"/>
      <geometry>
        <mesh filename="shape/visual/link_0_m2_vm.obj"/>
      </geometry>
    </visual>
    <visual name="link_0___3">
      <origin rpy="0.0 0.0 0.0" xyz="-0.10573799999999967 -0.1701922147503286 -0.1589604817222954"/>
      <geometry>
        <mesh filename="shape/visual/link_0_m3_vm.obj"/>
      </geometry>
    </visual>
    <collision>
      <origin rpy="0.0 0.0 0.0" xyz="-0.10573799999999967 -0.1701922147503286 -0.1589604817222954"/>
      <geometry>
        <mesh filename="shape/collision/link_0_cm.obj"/>
      </geometry>
    </collision>
  </link>
  <link name="base_link">
    <inertial>
      <origin rpy="0.0 0.0 0.0" xyz="0.0 0.0 0.0"/>
      <mass value="0.0"/>
      <inertia ixx="0.001" ixy="0.0" ixz="0.0" iyy="0.001" iyz="0.0" izz="0.001"/>
    </inertial>
    <visual name="link_1___1">
      <origin rpy="0.0 0.0 0.0" xyz="0.0 -0.0 0.0"/>
      <geometry>
        <mesh filename="shape/visual/link_1_m1_vm.obj"/>
      </geometry>
    </visual>
    <collision>
      <origin rpy="0.0 0.0 0.0" xyz="0.0 -0.0 0.0"/>
      <geometry>
        <mesh filename="shape/collision/link_1_cm.obj"/>
      </geometry>
    </collision>
  </link>
  <joint name="joint_0" type="revolute">
    <origin rpy="0.0 0.0 0.0" xyz="0.10573799999999967 0.1701922147503286 0.1589604817222954"/>
    <axis xyz="-1.0 -0.0 0.0"/>
    <parent link="base_link"/>
    <child link="link_0"/>
    <limit lower="-0.13194689145077132" upper="0.5089380098815459"/>
  </joint>
</robot>