<?xml version="1.0" ?>
<robot name="102621" version="1.0">
  <link name="link_0">
    <inertial>
      <origin rpy="0.0 0.0 0.0" xyz="0.0 0.0 0.0"/>
      <mass value="0.0"/>
      <inertia ixx="0.001" ixy="0.0" ixz="0.0" iyy="0.001" iyz="0.0" izz="0.001"/>
    </inertial>
    <visual name="link_0___3">
      <origin rpy="0.0 0.0 0.0" xyz="0.43970134167816566 -0.27999173164615954 -0.5636205013744164"/>
      <geometry>
        <mesh filename="shape/visual/link_0_m3_vm.obj"/>
      </geometry>
    </visual>
    <collision>
      <origin rpy="0.0 0.0 0.0" xyz="0.43970134167816566 -0.27999173164615954 -0.5636205013744164"/>
      <geometry>
        <mesh filename="shape/collision/link_0_cm.obj"/>
      </geometry>
    </collision>
  </link>
  <link name="link_1">
    <inertial>
      <origin rpy="0.0 0.0 0.0" xyz="0.0 0.0 0.0"/>
      <mass value="0.0"/>
      <inertia ixx="0.001" ixy="0.0" ixz="0.0" iyy="0.001" iyz="0.0" izz="0.001"/>
    </inertial>
    <visual name="link_1___2">
      <origin rpy="0.0 0.0 0.0" xyz="0.0 -0.03936250156839384 -0.08623833640126832"/>
      <geometry>
        <mesh filename="shape/visual/link_1_m2_vm.obj"/>
      </geometry>
    </visual>
    <collision>
      <origin rpy="0.0 0.0 0.0" xyz="0.0 -0.03936250156839384 -0.08623833640126832"/>
      <geometry>
        <mesh filename="shape/collision/link_1_cm.obj"/>
      </geometry>
    </collision>
  </link>
  <link name="link_2">
    <inertial>
      <origin rpy="0.0 0.0 0.0" xyz="0.0 0.0 0.0"/>
      <mass value="0.0"/>
      <inertia ixx="0.001" ixy="0.0" ixz="0.0" iyy="0.001" iyz="0.0" izz="0.001"/>
    </inertial>
    <visual name="link_2___2">
      <origin rpy="0.0 0.0 0.0" xyz="0.0 -0.03936250156839384 -0.08623833640126832"/>
      <geometry>
        <mesh filename="shape/visual/link_2_m2_vm.obj"/>
      </geometry>
    </visual>
    <collision>
      <origin rpy="0.0 0.0 0.0" xyz="0.0 -0.03936250156839384 -0.08623833640126832"/>
      <geometry>
        <mesh filename="shape/collision/link_2_cm.obj"/>
      </geometry>
    </collision>
  </link>
  <link name="link_3">
    <inertial>
      <origin rpy="0.0 0.0 0.0" xyz="0.0 0.0 0.0"/>
      <mass value="0.0"/>
      <inertia ixx="0.001" ixy="0.0" ixz="0.0" iyy="0.001" iyz="0.0" izz="0.001"/>
    </inertial>
    <visual name="link_3___1">
      <origin rpy="0.0 0.0 0.0" xyz="0.052322038705573115 -0.5060995377345119 -0.7277991002285853"/>
      <geometry>
        <mesh filename="shape/visual/link_3_m1_vm.obj"/>
      </geometry>
    </visual>
    <collision>
      <origin rpy="0.0 0.0 0.0" xyz="0.052322038705573115 -0.5060995377345119 -0.7277991002285853"/>
      <geometry>
        <mesh filename="shape/collision/link_3_cm.obj"/>
      </geometry>
    </collision>
  </link>
  <link name="base_link">
    <inertial>
      <origin rpy="0.0 0.0 0.0" xyz="0.0 0.0 0.0"/>
      <mass value="0.0"/>
      <inertia ixx="0.001" ixy="0.0" ixz="0.0" iyy="0.001" iyz="0.0" izz="0.001"/>
    </inertial>
    <visual name="link_4___1">
      <origin rpy="0.0 0.0 0.0" xyz="0.0 -0.0 0.0"/>
      <geometry>
        <mesh filename="shape/visual/link_4_m1_vm.obj"/>
      </geometry>
    </visual>
    <collision>
      <origin rpy="0.0 0.0 0.0" xyz="0.0 -0.0 0.0"/>
      <geometry>
        <mesh filename="shape/collision/link_4_cm.obj"/>
      </geometry>
    </collision>
  </link>
  <joint name="joint_0" type="revolute">
    <origin rpy="0.0 0.0 0.0" xyz="-0.43970134167816566 0.27999173164615954 0.5636205013744164"/>
    <axis xyz="-0.6417824432178281 -0.7666905658650205 -0.017345656255379007"/>
    <parent link="base_link"/>
    <child link="link_0"/>
    <limit lower="-0.0" upper="0.5717698629533422"/>
  </joint>
  <joint name="joint_1" type="revolute">
    <origin rpy="0.0 0.0 0.0" xyz="0.0 0.03936250156839384 0.08623833640126832"/>
    <axis xyz="-1.0 -0.0 0.0"/>
    <parent link="base_link"/>
    <child link="link_1"/>
    <limit lower="-0.0" upper="1.710422666954443"/>
  </joint>
  <joint name="joint_2" type="revolute">
    <origin rpy="0.0 0.0 0.0" xyz="0.0 0.03936250156839384 0.08623833640126832"/>
    <axis xyz="-1.0 -0.0 0.0"/>
    <parent link="base_link"/>
    <child link="link_2"/>
    <limit lower="-0.0" upper="1.710422666954443"/>
  </joint>
  <joint name="joint_3" type="prismatic">
    <origin rpy="0.0 0.0 0.0" xyz="-0.052322038705573115 0.5060995377345119 0.7277991002285853"/>
    <axis xyz="-0.005104721319804252 0.02642116669685537 0.9996378663149093"/>
    <parent link="base_link"/>
    <child link="link_3"/>
    <limit lower="0.0" upper="0.02"/>
  </joint>
</robot>