<?xml version="1.0" ?>
<robot name="102707" version="1.0">
  <link name="link_0">
  	<inertial>
      <origin rpy="0.0 0.0 0.0" xyz="0.0 0.0 0.0"/>
      <mass value="0.0"/>
      <inertia ixx="0.001" ixy="0.0" ixz="0.0" iyy="0.001" iyz="0.0" izz="0.001"/>
    </inertial>
    <visual name="link_0___3">
      <origin rpy="0.0 0.0 0.0" xyz="0.4264248258709862 -0.44278395488539674 -0.5515139014726672"/>
      <geometry>
        <mesh filename="shape/visual/link_0_m3_vm.obj"/>
      </geometry>
    </visual>
    <collision>
      <origin rpy="0.0 0.0 0.0" xyz="0.4264248258709862 -0.44278395488539674 -0.5515139014726672"/>
      <geometry>
        <mesh filename="shape/collision/link_0_cm.obj"/>
      </geometry>
    </collision>
  </link>
  <link name="link_1">
  	<inertial>
      <origin rpy="0.0 0.0 0.0" xyz="0.0 0.0 0.0"/>
      <mass value="0.0"/>
      <inertia ixx="0.001" ixy="0.0" ixz="0.0" iyy="0.001" iyz="0.0" izz="0.001"/>
    </inertial>
    <visual name="link_1___1">
      <origin rpy="0.0 0.0 0.0" xyz="0.0 -0.0 0.0"/>
      <geometry>
        <mesh filename="shape/visual/link_1_m1_vm.obj"/>
      </geometry>
    </visual>
    <collision>
      <origin rpy="0.0 0.0 0.0" xyz="0.0 -0.0 0.0"/>
      <geometry>
        <mesh filename="shape/collision/link_1_cm.obj"/>
      </geometry>
    </collision>
  </link>
  <link name="link_2">
  	<inertial>
      <origin rpy="0.0 0.0 0.0" xyz="0.0 0.0 0.0"/>
      <mass value="0.0"/>
      <inertia ixx="0.001" ixy="0.0" ixz="0.0" iyy="0.001" iyz="0.0" izz="0.001"/>
    </inertial>
    <visual name="link_2___2">
      <origin rpy="0.0 0.0 0.0" xyz="0.0 -0.009903901096258771 -0.09202221043028891"/>
      <geometry>
        <mesh filename="shape/visual/link_2_m2_vm.obj"/>
      </geometry>
    </visual>
    <collision>
      <origin rpy="0.0 0.0 0.0" xyz="0.0 -0.009903901096258771 -0.09202221043028891"/>
      <geometry>
        <mesh filename="shape/collision/link_2_cm.obj"/>
      </geometry>
    </collision>
  </link>
  <link name="link_3">
  	<inertial>
      <origin rpy="0.0 0.0 0.0" xyz="0.0 0.0 0.0"/>
      <mass value="0.0"/>
      <inertia ixx="0.001" ixy="0.0" ixz="0.0" iyy="0.001" iyz="0.0" izz="0.001"/>
    </inertial>
    <visual name="link_3___2">
      <origin rpy="0.0 0.0 0.0" xyz="0.0 -0.009903901096258771 -0.09202221043028891"/>
      <geometry>
        <mesh filename="shape/visual/link_3_m2_vm.obj"/>
      </geometry>
    </visual>
    <collision>
      <origin rpy="0.0 0.0 0.0" xyz="0.0 -0.009903901096258771 -0.09202221043028891"/>
      <geometry>
        <mesh filename="shape/collision/link_3_cm.obj"/>
      </geometry>
    </collision>
  </link>
  <link name="base_link">
  	<inertial>
      <origin rpy="0.0 0.0 0.0" xyz="0.0 0.0 0.0"/>
      <mass value="0.0"/>
      <inertia ixx="0.001" ixy="0.0" ixz="0.0" iyy="0.001" iyz="0.0" izz="0.001"/>
    </inertial>
    <visual name="link_4___1">
      <origin rpy="0.0 0.0 0.0" xyz="0.0 -0.0 0.0"/>
      <geometry>
        <mesh filename="shape/visual/link_4_m1_vm.obj"/>
      </geometry>
    </visual>
    <collision>
      <origin rpy="0.0 0.0 0.0" xyz="0.0 -0.0 0.0"/>
      <geometry>
        <mesh filename="shape/collision/link_4_cm.obj"/>
      </geometry>
    </collision>
  </link>
  <joint name="joint_0" type="revolute">
    <origin rpy="0.0 0.0 0.0" xyz="-0.4264248258709862 0.44278395488539674 0.5515139014726672"/>
    <axis xyz="0.9833508004441883 0.103909631067337 0.1490771338509839"/>
    <parent link="base_link"/>
    <child link="link_0"/>
    <limit lower="0.0" upper="0.5235987755982988"/>
  </joint>
  <joint name="joint_1" type="prismatic">
    <origin rpy="0.0 0.0 0.0" xyz="0.0 -0.0 0.0"/>
    <axis xyz="0.0 -0.0 1.0"/>
    <parent link="base_link"/>
    <child link="link_1"/>
    <limit lower="0.0" upper="0.03"/>
  </joint>
  <joint name="joint_2" type="revolute">
    <origin rpy="0.0 0.0 0.0" xyz="0.0 0.009903901096258771 0.09202221043028891"/>
    <axis xyz="-1.0 -0.0 0.0"/>
    <parent link="base_link"/>
    <child link="link_2"/>
    <limit lower="-0.0" upper="1.6929693744344996"/>
  </joint>
  <joint name="joint_3" type="revolute">
    <origin rpy="0.0 0.0 0.0" xyz="0.0 0.009903901096258771 0.09202221043028891"/>
    <axis xyz="-1.0 -0.0 0.0"/>
    <parent link="base_link"/>
    <child link="link_3"/>
    <limit lower="-0.0" upper="1.6929693744344996"/>
  </joint>
</robot>